File: Figures/ModellingMethod/globnomstuff/FORCE__X1_40_100_60mmGL.csv
time,A1,,Extensometer Strain,global stress,,Time,Extension,Load,Extension,,
0,0,0,0,0,,(sec),(mm),(kN),(mm),Strain,Stress
0.999964,0.212301,0.499982,0.012,0.00849204,,0,17.37342,0.01737342,0,0,0.000694937
8.99982,1.93696,4.49991,0.107,0.0774784,,0.8,129.86524,0.12986524,0.01337,0.1337,0.00519461
16.99998,3.62827,8.49999,0.202,0.1451308,,1.6,240.27149,0.24027149,0.02675,0.2675,0.00961086
24.9998,5.34731,12.4999,0.298,0.2138924,,2.4,355.73279,0.35573279,0.04056,0.4056,0.014229312
33,7.03382,16.5,0.393,0.2813528,,3.2,460.53212,0.46053212,0.05319,0.5319,0.018421285
40.9998,8.41143,20.4999,0.489,0.3364572,,4,565.49865,0.56549865,0.06631,0.6631,0.022619946
48.9998,8.95086,24.4999,0.673,0.3580344,,4.8,673.86548,0.67386548,0.08012,0.8012,0.026954619
57,9.24111,28.5,0.905,0.3696444,,5.6,784.01789,0.78401789,0.09344,0.9344,0.031360716
64.9998,9.45611,32.4999,1.167,0.3782444,,6.4,885.13587,0.88513587,0.10656,1.0656,0.035405435
72.9998,9.62419,36.4999,1.447,0.3849676,,7.2,988.62136,0.98862136,0.12012,1.2012,0.039544854
81,9.77682,40.5,1.744,0.3910728,,8,1085.57781,1.08557781,0.13331,1.3331,0.043423112
88.9998,9.89476,44.4999,2.057,0.3957904,,8.8,1183.00412,1.18300412,0.14719,1.4719,0.047320165
96.9998,10.0002,48.4999,2.379,0.400008,,9.6,1274.46391,1.27446391,0.15994,1.5994,0.050978556
104.9998,10.0958,52.4999,2.711,0.403832,,10.4,1361.96697,1.36196697,0.173,1.73,0.054478679
113,10.1876,56.5,3.056,0.407504,,11.2,1452.84012,1.45284012,0.18644,1.8644,0.058113605
121,10.256,60.5,3.412,0.41024,,12,1545.89573,1.54589573,0.20025,2.0025,0.061835829
128.9998,10.3343,64.4999,3.775,0.413372,,12.8,1628.40039,1.62840039,0.21325,2.1325,0.065136016
137,10.3915,68.5,4.15,0.41566,,13.6,1711.91134,1.71191134,0.22675,2.2675,0.068476454
145,10.4482,72.5,4.534,0.417928,,14.4,1794.25962,1.79425962,0.24,2.4,0.071770385
153,10.5003,76.5,4.92,0.420012,,15.2,1873.92905,1.87392905,0.25362,2.5362,0.074957162
161,10.5494,80.5,5.32,0.421976,,16,1958.0435,1.9580435,0.26694,2.6694,0.07832174
168.9998,10.6021,84.4999,5.73,0.424084,,16.8,2031.314,2.031314,0.27975,2.7975,0.08125256
176.9998,10.6367,88.4999,6.143,0.425468,,17.6,2109.52926,2.10952926,0.29306,2.9306,0.08438117
185,10.6761,92.5,6.574,0.427044,,18.4,2189.72266,2.18972266,0.307,3.07,0.087588906
192.9998,10.7095,96.4999,7.013,0.42838,,19.2,2264.23722,2.26423722,0.31994,3.1994,0.090569489
201,10.7372,100.5,7.468,0.429488,,20,2334.07989,2.33407989,0.33331,3.3331,0.093363196
209,10.7641,104.5,7.928,0.430564,,20.8,2405.5222,2.4055222,0.34675,3.4675,0.096220888
217,10.792,108.5,8.399,0.43168,,21.6,2473.3495,2.4733495,0.36012,3.6012,0.09893398
225,10.8135,112.5,8.889,0.43254,,22.4,2544.63647,2.54463647,0.37375,3.7375,0.101785459
233,10.8283,116.5,9.405,0.433132,,23.2,2606.92686,2.60692686,0.38644,3.8644,0.104277074
241,10.8501,120.5,9.923,0.434004,,24,2669.59965,2.66959965,0.39962,3.9962,0.106783986
249,10.871,124.5,10.466,0.43484,,24.8,2736.30116,2.73630116,0.41337,4.1337,0.109452046
257,10.8851,128.5,11.039,0.435404,,25.6,2802.87843,2.80287843,0.42675,4.2675,0.112115137
265,10.8952,132.5,11.63,0.435808,,26.4,2860.85568,2.86085568,0.43994,4.3994,0.114434227
273,10.9045,136.5,12.265,0.43618,,27.2,2921.55519,2.92155519,0.45337,4.5337,0.116862208
281,10.9152,140.5,12.913,0.436608,,28,2979.54418,2.97954418,0.46669,4.6669,0.119181767
289,10.9195,144.5,13.607,0.43678,,28.8,3041.30521,3.04130521,0.4805,4.805,0.121652208
297,10.9201,148.5,14.36,0.436804,,29.6,3099.20534,3.09920534,0.49337,4.9337,0.123968214
305,10.9209,152.5,15.162,0.436836,,30.4,3153.25074,3.15325074,0.50637,5.0637,0.12613003
313,10.914,156.5,16.02,0.43656,,31.2,3212.31596,3.21231596,0.51987,5.1987,0.128492638
321,10.8996,160.5,16.955,0.435984,,32,3273.01435,3.27301435,0.53356,5.3356,0.130920574
329,10.884,164.5,17.98,0.43536,,32.8,3327.00387,3.32700387,0.54656,5.4656,0.133080155
337,10.8546,168.5,19.09,0.434184,,33.6,3381.6725,3.3816725,0.56012,5.6012,0.1352669
345,10.815,172.5,20.291,0.4326,,34.4,3436.44135,3.43644135,0.57331,5.7331,0.137457654
353,10.7663,176.5,21.567,0.430652,,35.2,3489.20487,3.48920487,0.58687,5.8687,0.139568195
361,10.6908,180.5,22.908,0.427632,,36,3544.16482,3.54416482,0.60025,6.0025,0.141766593
369,10.612,184.5,24.29,0.42448,,36.8,3588.97895,3.58897895,0.613,6.13,0.143559158
377,10.5168,188.5,25.691,0.420672,,37.6,3638.71008,3.63871008,0.62637,6.2637,0.145548403
385,10.3947,192.5,27.111,0.415788,,38.4,3690.98,3.69098,0.64019,6.4019,0.1476392
393,10.2728,196.5,28.54,0.410912,,39.2,3736.78021,3.73678021,0.65331,6.5331,0.149471208
401,10.1375,200.5,29.979,0.4055,,40,3782.43588,3.78243588,0.66662,6.6662,0.151297435
409,9.97515,204.5,31.433,0.399006,,40.8,3833.43361,3.83343361,0.68,6.8,0.153337344
417,9.81404,208.5,32.893,0.3925616,,41.6,3886.26419,3.88626419,0.6935,6.935,0.155450568
425,9.62385,212.5,34.371,0.384954,,42.4,3945.71051,3.94571051,0.70719,7.0719,0.15782842
433,9.43282,216.5,35.848,0.3773128,,43.2,3992.83133,3.99283133,0.71981,7.1981,0.159713253
441,9.23286,220.5,37.335,0.3693144,,44,4042.26519,4.04226519,0.73312,7.3312,0.161690608
449,9.02575,224.5,38.824,0.36103,,44.8,4093.10982,4.09310982,0.74669,7.4669,0.163724393
457,8.8038,228.5,40.324,0.352152,,45.6,4145.60139,4.14560139,0.76006,7.6006,0.165824056
465,8.58797,232.5,41.825,0.3435188,,46.4,4190.80406,4.19080406,0.77319,7.7319,0.167632162
473,8.36697,236.5,43.328,0.3346788,,47.2,4241.63081,4.24163081,0.78681,7.8681,0.169665232
481,8.14227,240.5,44.827,0.3256908,,48,4288.3385,4.2883385,0.79975,7.9975,0.17153354
489,7.92839,244.5,46.327,0.3171356,,48.8,4339.58173,4.33958173,0.81375,8.1375,0.173583269
497,7.70797,248.5,47.823,0.3083188,,49.6,4387.69795,4.38769795,0.82662,8.2662,0.175507918
505,7.4968,252.5,49.316,0.299872,,50.4,4431.74504,4.43174504,0.83962,8.3962,0.177269802
513,7.28823,256.5,50.811,0.2915292,,51.2,4481.90272,4.48190272,0.85319,8.5319,0.179276109
521,7.08461,260.5,52.296,0.2833844,,52,4536.01554,4.53601554,0.86687,8.6687,0.181440622
529,6.88388,264.5,53.778,0.2753552,,52.8,4581.79265,4.58179265,0.87987,8.7987,0.183271706
537,6.68916,268.5,55.259,0.2675664,,53.6,4632.36421,4.63236421,0.8935,8.935,0.185294568
545,6.50712,272.5,56.731,0.2602848,,54.4,4682.28497,4.68228497,0.90662,9.0662,0.187291399
553,6.33195,276.5,58.195,0.253278,,55.2,4732.69969,4.73269969,0.9205,9.205,0.189307988
561,6.15828,280.5,59.657,0.2463312,,56,4784.28528,4.78428528,0.93356,9.3356,0.191371411
569,6.0058,284.5,61.106,0.240232,,56.8,4828.69968,4.82869968,0.94637,9.4637,0.193147987
577,5.84789,288.5,62.559,0.2339156,,57.6,4878.44497,4.87844497,0.95981,9.5981,0.195137799
585,5.70636,292.5,64,0.2282544,,58.4,4931.73711,4.93173711,0.9735,9.735,0.197269484
593,5.56904,296.5,65.436,0.2227616,,59.2,4980.40095,4.98040095,0.9865,9.865,0.199216038
600,5.44942,300,66.694,0.2179768,,60,5029.09832,5.02909832,0.99994,9.9994,0.201163933
,,,,,,60.8,5081.46361,5.08146361,1.01337,10.1337,0.203258544
,,,,,,61.6,5129.46174,5.12946174,1.02662,10.2662,0.20517847
,,,,,,62.4,5184.17917,5.18417917,1.0405,10.405,0.207367167
,,,,,,63.2,5229.74245,5.22974245,1.05319,10.5319,0.209189698
,,,,,,64,5276.06234,5.27606234,1.06631,10.6631,0.211042494
,,,,,,64.8,5327.93514,5.32793514,1.08006,10.8006,0.213117406
,,,,,,65.60001,5382.29272,5.38229272,1.09344,10.9344,0.215291709
,,,,,,66.4,5427.55909,5.42755909,1.10662,11.0662,0.217102364
,,,,,,67.20001,5479.34175,5.47934175,1.12019,11.2019,0.21917367
,,,,,,68,5526.9137,5.5269137,1.13337,11.3337,0.221076548
,,,,,,68.8,5578.28769,5.57828769,1.14712,11.4712,0.223131508
,,,,,,69.60001,5624.76851,5.62476851,1.16,11.6,0.22499074
,,,,,,70.4,5669.05998,5.66905998,1.17306,11.7306,0.226762399
,,,,,,71.20001,5716.63342,5.71663342,1.18644,11.8644,0.228665337
,,,,,,72,5768.72677,5.76872677,1.20019,12.0019,0.230749071
,,,,,,72.8,5813.3129,5.8133129,1.21325,12.1325,0.232532516
,,,,,,73.60001,5859.7751,5.8597751,1.22681,12.2681,0.234391004
,,,,,,74.4,5907.50501,5.90750501,1.24,12.4,0.2363002
,,,,,,75.20001,5952.85408,5.95285408,1.2535,12.535,0.238114163
,,,,,,76,6001.69487,6.00169487,1.26694,12.6694,0.240067795
,,,,,,76.8,6040.40176,6.04040176,1.27981,12.7981,0.24161607
,,,,,,77.60001,6082.53218,6.08253218,1.29306,12.9306,0.243301287
,,,,,,78.4,6129.84747,6.12984747,1.30706,13.0706,0.245193899
,,,,,,79.20001,6172.31987,6.17231987,1.32,13.2,0.246892795
,,,,,,80,6211.8955,6.2118955,1.33331,13.3331,0.24847582
,,,,,,80.8,6256.2868,6.2562868,1.34675,13.4675,0.250251472
,,,,,,81.60001,6295.74209,6.29574209,1.36019,13.6019,0.251829684
,,,,,,82.4,6339.40995,6.33940995,1.37375,13.7375,0.253576398
,,,,,,83.20001,6375.13846,6.37513846,1.3865,13.865,0.255005538
,,,,,,84.00001,6410.9765,6.4109765,1.39956,13.9956,0.25643906
,,,,,,84.8,6452.14543,6.45214543,1.41337,14.1337,0.258085817
,,,,,,85.60001,6493.34118,6.49334118,1.42675,14.2675,0.259733647
,,,,,,86.4,6528.76645,6.52876645,1.44,14.4,0.261150658
,,,,,,87.20001,6566.41498,6.56641498,1.45344,14.5344,0.262656599
,,,,,,88.00001,6601.43942,6.60143942,1.46675,14.6675,0.264057577
,,,,,,88.8,6639.43216,6.63943216,1.48044,14.8044,0.265577286
,,,,,,89.60001,6673.96635,6.67396635,1.49337,14.9337,0.266958654
,,,,,,90.4,6702.77327,6.70277327,1.50637,15.0637,0.268110931
,,,,,,91.20001,6737.11002,6.73711002,1.51987,15.1987,0.269484401
,,,,,,92.00001,6773.47854,6.77347854,1.53356,15.3356,0.270939142
,,,,,,92.8,6802.32868,6.80232868,1.54662,15.4662,0.272093147
,,,,,,93.60001,6832.49235,6.83249235,1.56012,15.6012,0.273299694
,,,,,,94.4,6864.86214,6.86486214,1.57331,15.7331,0.274594486
,,,,,,95.20001,6894.22414,6.89422414,1.58675,15.8675,0.275768966
,,,,,,96.00001,6926.59318,6.92659318,1.60025,16.0025,0.277063727
,,,,,,96.8,6949.96119,6.94996119,1.61294,16.1294,0.277998448
,,,,,,97.60001,6977.53727,6.97753727,1.62637,16.2637,0.279101491
,,,,,,98.4,7011.04403,7.01104403,1.64025,16.4025,0.280441761
,,,,,,99.20001,7037.86239,7.03786239,1.65331,16.5331,0.281514496
,,,,,,100.00001,7062.30029,7.06230029,1.66662,16.6662,0.282492012
,,,,,,100.8,7086.4208,7.0864208,1.68,16.8,0.283456832
,,,,,,101.60001,7086.84474,7.08684474,1.6935,16.935,0.28347379
,,,,,,102.4,7128.19546,7.12819546,1.70712,17.0712,0.285127818
,,,,,,103.20001,7159.99901,7.15999901,1.71981,17.1981,0.28639996
,,,,,,104.00001,7186.25709,7.18625709,1.73312,17.3312,0.287450284
,,,,,,104.8,7213.19914,7.21319914,1.74669,17.4669,0.288527966
,,,,,,105.60001,7241.2543,7.2412543,1.76006,17.6006,0.289650172
,,,,,,106.4,7261.79704,7.26179704,1.77319,17.7319,0.290471882
,,,,,,107.20001,7287.8696,7.2878696,1.78675,17.8675,0.291514784
,,,,,,108.00001,7310.75779,7.31075779,1.79975,17.9975,0.292430312
,,,,,,108.8,7336.61428,7.33661428,1.81369,18.1369,0.293464571
,,,,,,109.60001,7360.77502,7.36077502,1.82669,18.2669,0.294431001
,,,,,,110.4,7379.29344,7.37929344,1.83962,18.3962,0.295171738
,,,,,,111.20001,7402.72999,7.40272999,1.85325,18.5325,0.2961092
,,,,,,112.00001,7430.02892,7.43002892,1.86681,18.6681,0.297201157
,,,,,,112.8,7449.992,7.449992,1.87994,18.7994,0.29799968
,,,,,,113.60001,7474.93953,7.47493953,1.89356,18.9356,0.298997581
,,,,,,114.40001,7497.05285,7.49705285,1.90662,19.0662,0.299882114
,,,,,,115.20001,7520.08632,7.52008632,1.92044,19.2044,0.300803453
,,,,,,116.00001,7543.7665,7.5437665,1.93356,19.3356,0.30175066
,,,,,,116.8,7559.15567,7.55915567,1.94644,19.4644,0.302366227
,,,,,,117.60001,7579.93385,7.57993385,1.95981,19.5981,0.303197354
,,,,,,118.40001,7604.4865,7.6044865,1.97344,19.7344,0.30417946
,,,,,,119.20001,7624.48683,7.62448683,1.9865,19.865,0.304979473
,,,,,,120.00001,7645.00499,7.64500499,2,20,0.3058002
,,,,,,120.8,7667.60781,7.66760781,2.01337,20.1337,0.306704312
,,,,,,121.60001,7686.7573,7.6867573,2.02662,20.2662,0.307470292
,,,,,,122.40001,7711.82328,7.71182328,2.0405,20.405,0.308472931
,,,,,,123.20001,7728.01414,7.72801414,2.05325,20.5325,0.309120566
,,,,,,124.00001,7744.05748,7.74405748,2.06631,20.6631,0.309762299
,,,,,,124.8,7767.09318,7.76709318,2.08012,20.8012,0.310683727
,,,,,,125.60001,7791.46701,7.79146701,2.09344,20.9344,0.31165868
,,,,,,126.40001,7806.85768,7.80685768,2.10662,21.0662,0.312274307
,,,,,,127.20001,7828.95982,7.82895982,2.12019,21.2019,0.313158393
,,,,,,128,7846.06785,7.84606785,2.13344,21.3344,0.313842714
,,,,,,128.8,7868.39724,7.86839724,2.14712,21.4712,0.31473589
,,,,,,129.60001,7886.0864,7.8860864,2.16,21.6,0.315443456
,,,,,,130.40001,7901.40331,7.90140331,2.17306,21.7306,0.316056132
,,,,,,131.20002,7921.02665,7.92102665,2.1865,21.865,0.316841066
,,,,,,132,7942.93955,7.94293955,2.20012,22.0012,0.317717582
,,,,,,132.8,7960.04012,7.96004012,2.21325,22.1325,0.318401605
,,,,,,133.6,7978.60995,7.97860995,2.22681,22.2681,0.319144398
,,,,,,134.40002,7998.06938,7.99806938,2.24,22.4,0.319922775
,,,,,,135.20002,8015.91799,8.01591799,2.2535,22.535,0.32063672
,,,,,,136,8037.9352,8.0379352,2.267,22.67,0.321517408
,,,,,,136.8,8050.16235,8.05016235,2.27981,22.7981,0.322006494
,,,,,,137.6,8067.26366,8.06726366,2.29306,22.9306,0.322690546
,,,,,,138.40002,8090.19655,8.09019655,2.30706,23.0706,0.323607862
,,,,,,139.20002,8107.43347,8.10743347,2.32,23.2,0.324297339
,,,,,,140,8122.7392,8.1227392,2.33337,23.3337,0.324909568
,,,,,,140.8,8142.64193,8.14264193,2.34675,23.4675,0.325705677
,,,,,,141.6,8158.99596,8.15899596,2.36025,23.6025,0.326359838
,,,,,,142.40002,8178.4077,8.1784077,2.37369,23.7369,0.327136308
,,,,,,143.20002,8192.61447,8.19261447,2.3865,23.865,0.327704579
,,,,,,144,8206.66552,8.20666552,2.39956,23.9956,0.328266621
,,,,,,144.8,8227.02199,8.22702199,2.41337,24.1337,0.32908088
,,,,,,145.6,8247.05362,8.24705362,2.42681,24.2681,0.329882145
,,,,,,146.40002,8261.34682,8.26134682,2.44006,24.4006,0.330453873
,,,,,,147.20002,8278.5435,8.2785435,2.45337,24.5337,0.33114174
,,,,,,148,8294.17184,8.29417184,2.46675,24.6675,0.331766874
,,,,,,148.8,8313.82498,8.31382498,2.4805,24.805,0.332552999
,,,,,,149.6,8329.5621,8.3295621,2.49344,24.9344,0.333182484
,,,,,,150.40002,8340.52339,8.34052339,2.50644,25.0644,0.333620936
,,,,,,151.20002,8358.64171,8.35864171,2.51987,25.1987,0.334345668
,,,,,,152,8378.25686,8.37825686,2.53356,25.3356,0.335130274
,,,,,,152.8,8392.52472,8.39252472,2.54662,25.4662,0.335700989
,,,,,,153.6,8408.46226,8.40846226,2.56012,25.6012,0.33633849
,,,,,,154.40002,8425.23426,8.42523426,2.57337,25.7337,0.33700937
,,,,,,155.20002,8439.0156,8.4390156,2.58662,25.8662,0.337560624
,,,,,,156,8458.94665,8.45894665,2.60025,26.0025,0.338357866
,,,,,,156.8,8468.04231,8.46804231,2.61294,26.1294,0.338721692
,,,,,,157.6,8483.33314,8.48333314,2.62637,26.2637,0.339333326
,,,,,,158.40002,8503.72612,8.50372612,2.64012,26.4012,0.340149045
,,,,,,159.20002,8519.49751,8.51949751,2.65331,26.5331,0.3407799
,,,,,,160,8533.03596,8.53303596,2.66669,26.6669,0.341321438
,,,,,,160.8,8548.91166,8.54891166,2.67994,26.7994,0.341956466
,,,,,,161.6,8563.97972,8.56397972,2.6935,26.935,0.342559189
,,,,,,162.40002,8583.60082,8.58360082,2.70719,27.0719,0.343344033
,,,,,,163.20002,8592.7695,8.5927695,2.71981,27.1981,0.34371078
,,,,,,164.00002,8606.41599,8.60641599,2.73312,27.3312,0.34425664
,,,,,,164.8,8622.38035,8.62238035,2.74662,27.4662,0.344895214
,,,,,,165.6,8640.51357,8.64051357,2.76006,27.6006,0.345620543
,,,,,,166.40002,8651.87272,8.65187272,2.77312,27.7312,0.346074909
,,,,,,167.20002,8668.61343,8.66861343,2.78675,27.8675,0.346744537
,,,,,,168.00002,8681.26452,8.68126452,2.79981,27.9981,0.347250581
,,,,,,168.8,8697.23186,8.69723186,2.81369,28.1369,0.347889274
,,,,,,169.6,8713.12246,8.71312246,2.82669,28.2669,0.348524898
,,,,,,170.40002,8722.76723,8.72276723,2.83962,28.3962,0.348910689
,,,,,,171.20002,8736.99188,8.73699188,2.85325,28.5325,0.349479675
,,,,,,172.00002,8756.60405,8.75660405,2.86687,28.6687,0.350264162
,,,,,,172.8,8767.3381,8.7673381,2.87994,28.7994,0.350693524
,,,,,,173.6,8782.06342,8.78206342,2.89356,28.9356,0.351282537
,,,,,,174.40002,8795.809,8.795809,2.90662,29.0662,0.35183236
,,,,,,175.20002,8811.19221,8.81119221,2.9205,29.205,0.352447688
,,,,,,176.00002,8827.33017,8.82733017,2.93356,29.3356,0.353093207
,,,,,,176.8,8834.88655,8.83488655,2.94644,29.4644,0.353395462
,,,,,,177.6,8848.57252,8.84857252,2.95981,29.5981,0.353942901
,,,,,,178.40002,8865.18583,8.86518583,2.9735,29.735,0.354607433
,,,,,,179.20002,8876.55169,8.87655169,2.9865,29.865,0.355062068
,,,,,,180.00002,8889.09176,8.88909176,2.99994,29.9994,0.35556367
,,,,,,180.8,8904.39004,8.90439004,3.01337,30.1337,0.356175602
,,,,,,181.6,8916.24764,8.91624764,3.02662,30.2662,0.356649906
,,,,,,182.40002,8934.12679,8.93412679,3.0405,30.405,0.357365072
,,,,,,183.20002,8943.79541,8.94379541,3.05325,30.5325,0.357751816
,,,,,,184.00002,8952.58784,8.95258784,3.06637,30.6637,0.358103514
,,,,,,184.8,8967.69315,8.96769315,3.08012,30.8012,0.358707726
,,,,,,185.6,8985.3242,8.9853242,3.09344,30.9344,0.359412968
,,,,,,186.40002,8993.77167,8.99377167,3.10669,31.0669,0.359750867
,,,,,,187.20002,9008.92988,9.00892988,3.12019,31.2019,0.360357195
,,,,,,188.00002,9019.76898,9.01976898,3.13337,31.3337,0.360790759
,,,,,,188.8,9034.95923,9.03495923,3.14712,31.4712,0.361398369
,,,,,,189.6,9046.20737,9.04620737,3.16,31.6,0.361848295
,,,,,,190.40002,9054.23462,9.05423462,3.173,31.73,0.362169385
,,,,,,191.20002,9067.70602,9.06770602,3.1865,31.865,0.362708241
,,,,,,192.00002,9083.18907,9.08318907,3.20019,32.0019,0.363327563
,,,,,,192.8,9092.8711,9.0928711,3.21325,32.1325,0.363714844
,,,,,,193.6,9104.75329,9.10475329,3.22681,32.2681,0.364190132
,,,,,,194.40002,9118.37146,9.11837146,3.24,32.4,0.364734858
,,,,,,195.20002,9130.23949,9.13023949,3.2535,32.535,0.36520958
,,,,,,196.00002,9145.72999,9.14572999,3.267,32.67,0.3658292
,,,,,,196.8,9152.64487,9.15264487,3.27981,32.7981,0.366105795
,,,,,,197.6,9162.5683,9.1625683,3.29306,32.9306,0.366502732
,,,,,,198.40002,9178.97299,9.17897299,3.30706,33.0706,0.36715892
,,,,,,199.20002,9190.29266,9.19029266,3.32006,33.2006,0.367611706
,,,,,,200.00002,9199.66772,9.19966772,3.33337,33.3337,0.367986709
,,,,,,200.8,9212.89474,9.21289474,3.34675,33.4675,0.36851579
,,,,,,201.6,9223.00965,9.22300965,3.36019,33.6019,0.368920386
,,,,,,202.40002,9237.07113,9.23707113,3.37369,33.7369,0.369482845
,,,,,,203.20002,9243.53674,9.24353674,3.3865,33.865,0.36974147
,,,,,,204.00002,9251.68023,9.25168023,3.39956,33.9956,0.370067209
,,,,,,204.8,9265.88774,9.26588774,3.41344,34.1344,0.37063551
,,,,,,205.6,9279.49995,9.27949995,3.42681,34.2681,0.371179998
,,,,,,206.40002,9287.62779,9.28762779,3.43994,34.3994,0.371505112
,,,,,,207.20002,9300.84214,9.30084214,3.45331,34.5331,0.372033686
,,,,,,208.00002,9311.25656,9.31125656,3.46675,34.6675,0.372450262
,,,,,,208.8,9324.57447,9.32457447,3.48037,34.8037,0.372982979
,,,,,,209.6,9336.08487,9.33608487,3.49344,34.9344,0.373443395
,,,,,,210.40002,9341.47239,9.34147239,3.50644,35.0644,0.373658896
,,,,,,211.20002,9352.65422,9.35265422,3.51987,35.1987,0.374106169
,,,,,,212.00002,9366.98988,9.36698988,3.53356,35.3356,0.374679595
,,,,,,212.8,9375.21681,9.37521681,3.54669,35.4669,0.375008672
,,,,,,213.6,9384.91002,9.38491002,3.56019,35.6019,0.375396401
,,,,,,214.40002,9396.37944,9.39637944,3.57331,35.7331,0.375855178
,,,,,,215.20002,9405.47884,9.40547884,3.58669,35.8669,0.376219154
,,,,,,216.00002,9418.9629,9.4189629,3.60025,36.0025,0.376758516
,,,,,,216.8,9422.14131,9.42214131,3.61294,36.1294,0.376885652
,,,,,,217.6,9431.7086,9.4317086,3.62637,36.2637,0.377268344
,,,,,,218.40002,9447.22146,9.44722146,3.64019,36.4019,0.377888858
,,,,,,219.20002,9457.17618,9.45717618,3.65331,36.5331,0.378287047
,,,,,,220.00002,9465.45452,9.46545452,3.66662,36.6662,0.378618181
,,,,,,220.8,9477.13256,9.47713256,3.67994,36.7994,0.379085302
,,,,,,221.6,9485.77076,9.48577076,3.6935,36.935,0.37943083
,,,,,,222.40002,9499.66013,9.49966013,3.70712,37.0712,0.379986405
,,,,,,223.20002,9504.84127,9.50484127,3.71981,37.1981,0.380193651
,,,,,,224.00002,9512.55038,9.51255038,3.73319,37.3319,0.380502015
,,,,,,224.8,9522.02678,9.52202678,3.74662,37.4662,0.380881071
,,,,,,225.6,9534.94385,9.53494385,3.76006,37.6006,0.381397754
,,,,,,226.40002,9540.9371,9.5409371,3.77312,37.7312,0.381637484
,,,,,,227.20002,9553.17318,9.55317318,3.78675,37.8675,0.382126927
,,,,,,228.00002,9560.53957,9.56053957,3.79981,37.9981,0.382421583
,,,,,,228.80002,9571.36229,9.57136229,3.81362,38.1362,0.382854492
,,,,,,229.6,9582.13806,9.58213806,3.82669,38.2669,0.383285522
,,,,,,230.40002,9585.47369,9.58547369,3.83956,38.3956,0.383418948
,,,,,,231.20002,9595.9112,9.5959112,3.85319,38.5319,0.383836448
,,,,,,232.00002,9610.05464,9.61005464,3.86687,38.6687,0.384402186
,,,,,,232.80002,9615.56286,9.61556286,3.87994,38.7994,0.384622514
,,,,,,233.6,9626.93542,9.62693542,3.89362,38.9362,0.385077417
,,,,,,234.40002,9635.46559,9.63546559,3.90669,39.0669,0.385418624
,,,,,,235.20002,9645.12005,9.64512005,3.92056,39.2056,0.385804802
,,,,,,236.00002,9654.33419,9.65433419,3.9335,39.335,0.386173368
,,,,,,236.80002,9658.32248,9.65832248,3.94644,39.4644,0.386332899
,,,,,,237.6,9666.23425,9.66623425,3.95981,39.5981,0.38664937
,,,,,,238.40002,9677.31997,9.67731997,3.97344,39.7344,0.387092799
,,,,,,239.20002,9684.59249,9.68459249,3.9865,39.865,0.3873837
,,,,,,240.00002,9693.1383,9.6931383,4.00006,40.0006,0.387725532
,,,,,,240.80002,9702.91272,9.70291272,4.01331,40.1331,0.388116509
,,,,,,241.6,9709.61601,9.70961601,4.02656,40.2656,0.38838464
,,,,,,242.40002,9721.96311,9.72196311,4.0405,40.405,0.388878524
,,,,,,243.20002,9728.08003,9.72808003,4.05331,40.5331,0.389123201
,,,,,,244.00002,9731.74348,9.73174348,4.06631,40.6631,0.389269739
,,,,,,244.80002,9742.54906,9.74254906,4.08012,40.8012,0.389701962
,,,,,,245.6,9755.17035,9.75517035,4.09344,40.9344,0.390206814
,,,,,,246.40002,9759.01932,9.75901932,4.10669,41.0669,0.390360773
,,,,,,247.20002,9770.24138,9.77024138,4.12019,41.2019,0.390809655
,,,,,,248.00002,9776.25251,9.77625251,4.13344,41.3344,0.3910501
,,,,,,248.80002,9785.68867,9.78568867,4.14706,41.4706,0.391427547
,,,,,,249.6,9792.02315,9.79202315,4.16,41.6,0.391680926
,,,,,,250.40002,9796.19399,9.79619399,4.17306,41.7306,0.39184776
,,,,,,251.20002,9803.68778,9.80368778,4.18644,41.8644,0.392147511
,,,,,,252.00002,9814.72805,9.81472805,4.20019,42.0019,0.392589122
,,,,,,252.80002,9821.0074,9.8210074,4.21325,42.1325,0.392840296
,,,,,,253.6,9828.61593,9.82861593,4.22681,42.2681,0.393144637
,,,,,,254.40002,9837.86583,9.83786583,4.24,42.4,0.393514633
,,,,,,255.20002,9844.02001,9.84402001,4.25337,42.5337,0.3937608
,,,,,,256,9856.22704,9.85622704,4.267,42.67,0.394249082
,,,,,,256.80002,9857.44819,9.85744819,4.27987,42.7987,0.394297928
,,,,,,257.6,9863.13894,9.86313894,4.29306,42.9306,0.394525558
,,,,,,258.40003,9874.6486,9.8746486,4.307,43.07,0.394985944
,,,,,,259.20002,9881.54113,9.88154113,4.32006,43.2006,0.395261645
,,,,,,260,9885.65758,9.88565758,4.33331,43.3331,0.395426303
,,,,,,260.80002,9895.31353,9.89531353,4.34675,43.4675,0.395812541
,,,,,,261.6,9901.48485,9.90148485,4.36019,43.6019,0.396059394
,,,,,,262.40003,9911.15421,9.91115421,4.37369,43.7369,0.396446168
,,,,,,263.2,9914.60457,9.91460457,4.3865,43.865,0.396584183
,,,,,,264,9918.30751,9.91830751,4.39956,43.9956,0.3967323
,,,,,,264.80003,9927.74963,9.92774963,4.41337,44.1337,0.397109985
,,,,,,265.6,9937.07329,9.93707329,4.42675,44.2675,0.397482932
,,,,,,266.40003,9943.223,9.943223,4.44,44.4,0.39772892
,,,,,,267.2,9951.17053,9.95117053,4.45337,44.5337,0.398046821
,,,,,,268,9956.29281,9.95629281,4.46669,44.6669,0.398251712
,,,,,,268.80003,9966.02029,9.96602029,4.48037,44.8037,0.398640812
,,,,,,269.6,9972.63566,9.97263566,4.49344,44.9344,0.398905426
,,,,,,270.40003,9973.35762,9.97335762,4.50644,45.0644,0.398934305
,,,,,,271.2,9980.5139,9.9805139,4.51987,45.1987,0.399220556
,,,,,,272,9990.5014,9.9905014,4.53362,45.3362,0.399620056
,,,,,,272.80003,9994.6849,9.9946849,4.54669,45.4669,0.399787396
,,,,,,273.6,9999.94725,9.99994725,4.56019,45.6019,0.39999789
,,,,,,274.40003,10007.79867,10.00779867,4.57337,45.7337,0.400311947
,,,,,,275.2,10011.93821,10.01193821,4.58662,45.8662,0.400477528
,,,,,,276,10021.75808,10.02175808,4.60025,46.0025,0.400870323
,,,,,,276.80003,10022.09038,10.02209038,4.61287,46.1287,0.400883615
,,,,,,277.6,10028.17601,10.02817601,4.62644,46.2644,0.40112704
,,,,,,278.40003,10038.75434,10.03875434,4.64019,46.4019,0.401550174
,,,,,,279.2,10044.83104,10.04483104,4.65331,46.5331,0.401793242
,,,,,,280,10048.75675,10.04875675,4.66669,46.6669,0.40195027
,,,,,,280.80003,10056.17604,10.05617604,4.67994,46.7994,0.402247042
,,,,,,281.6,10060.91461,10.06091461,4.6935,46.935,0.402436584
,,,,,,282.40003,10072.01597,10.07201597,4.70712,47.0712,0.402880639
,,,,,,283.2,10072.80424,10.07280424,4.71987,47.1987,0.40291217
,,,,,,284,10076.24567,10.07624567,4.73312,47.3312,0.403049827
,,,,,,284.80003,10082.85359,10.08285359,4.74669,47.4669,0.403314144
,,,,,,285.6,10092.30539,10.09230539,4.76006,47.6006,0.403692216
,,,,,,286.40003,10094.51225,10.09451225,4.77319,47.7319,0.40378049
,,,,,,287.2,10101.65513,10.10165513,4.78675,47.8675,0.404066205
,,,,,,288,10106.05618,10.10605618,4.79975,47.9975,0.404242247
,,,,,,288.80003,10112.60301,10.11260301,4.81362,48.1362,0.40450412
,,,,,,289.6,10119.19752,10.11919752,4.82669,48.2669,0.404767901
,,,,,,290.40003,10120.06626,10.12006626,4.83956,48.3956,0.40480265
,,,,,,291.2,10126.40521,10.12640521,4.85325,48.5325,0.405056208
,,,,,,292,10134.95997,10.13495997,4.86681,48.6681,0.405398399
,,,,,,292.80003,10137.89549,10.13789549,4.87994,48.7994,0.40551582
,,,,,,293.6,10145.72531,10.14572531,4.89362,48.9362,0.405829012
,,,,,,294.40003,10150.33871,10.15033871,4.90669,49.0669,0.406013548
,,,,,,295.2,10156.33494,10.15633494,4.9205,49.205,0.406253398
,,,,,,296,10164.00829,10.16400829,4.93356,49.3356,0.406560332
,,,,,,296.80003,10163.17308,10.16317308,4.94644,49.4644,0.406526923
,,,,,,297.6,10167.32678,10.16732678,4.95981,49.5981,0.406693071
,,,,,,298.40003,10176.48503,10.17648503,4.97344,49.7344,0.407059401
,,,,,,299.2,10179.63365,10.17963365,4.9865,49.865,0.407185346
,,,,,,300,10183.97957,10.18397957,5,50,0.407359183
,,,,,,300.80003,10190.28351,10.19028351,5.01331,50.1331,0.40761134
,,,,,,301.6,10194.41038,10.19441038,5.02656,50.2656,0.407776415
,,,,,,302.40003,10203.04859,10.20304859,5.04056,50.4056,0.408121944
,,,,,,303.2,10204.27048,10.20427048,5.05325,50.5325,0.408170819
,,,,,,304,10205.40521,10.20540521,5.06631,50.6631,0.408216208
,,,,,,304.80003,10212.63227,10.21263227,5.08019,50.8019,0.408505291
,,,,,,305.6,10221.69441,10.22169441,5.09344,50.9344,0.408867776
,,,,,,306.40003,10222.1854,10.2221854,5.10662,51.0662,0.408887416
,,,,,,307.2,10229.39831,10.22939831,5.12025,51.2025,0.409175932
,,,,,,308,10231.62976,10.23162976,5.13344,51.3344,0.40926519
,,,,,,308.80003,10238.73687,10.23873687,5.14706,51.4706,0.409549475
,,,,,,309.6,10242.40032,10.24240032,5.16,51.6,0.409696013
,,,,,,310.40003,10241.92721,10.24192721,5.17306,51.7306,0.409677088
,,,,,,311.2,10247.24767,10.24724767,5.1865,51.865,0.409889907
,,,,,,312,10255.17359,10.25517359,5.20012,52.0012,0.410206944
,,,,,,312.80003,10257.64942,10.25764942,5.21331,52.1331,0.410305977
,,,,,,313.6,10260.95375,10.26095375,5.22675,52.2675,0.41043815
,,,,,,314.40003,10266.94849,10.26694849,5.24,52.4,0.41067794
,,,,,,315.2,10269.32746,10.26932746,5.25344,52.5344,0.410773098
,,,,,,316,10277.28841,10.27728841,5.26706,52.6706,0.411091536
,,,,,,316.80003,10276.42041,10.27642041,5.27987,52.7987,0.411056816
,,,,,,317.6,10279.45578,10.27945578,5.29306,52.9306,0.411178231
,,,,,,318.40003,10288.18935,10.28818935,5.30706,53.0706,0.411527574
,,,,,,319.2,10292.10463,10.29210463,5.32006,53.2006,0.411684185
,,,,,,320,10294.28467,10.29428467,5.33337,53.3337,0.411771387
,,,,,,320.80003,10300.72197,10.30072197,5.34675,53.4675,0.412028879
,,,,,,321.6,10302.61219,10.30261219,5.36019,53.6019,0.412104488
,,,,,,322.40003,10308.8893,10.3088893,5.37362,53.7362,0.412355572
,,,,,,323.2,10308.94071,10.30894071,5.3865,53.865,0.412357628
,,,,,,324.00003,10309.01372,10.30901372,5.39956,53.9956,0.412360549
,,,,,,324.80003,10316.11338,10.31611338,5.41337,54.1337,0.412644535
,,,,,,325.6,10322.87106,10.32287106,5.42681,54.2681,0.412914842
,,,,,,326.40003,10323.73607,10.32373607,5.44006,54.4006,0.412949443
,,,,,,327.2,10327.45764,10.32745764,5.45337,54.5337,0.413098306
,,,,,,328.00003,10330.56751,10.33056751,5.46675,54.6675,0.4132227
,,,,,,328.80003,10336.03624,10.33603624,5.48044,54.8044,0.41344145
,,,,,,329.6,10339.0567,10.3390567,5.49344,54.9344,0.413562268
,,,,,,330.40003,10338.26843,10.33826843,5.50644,55.0644,0.413530737
,,,,,,331.2,10342.06375,10.34206375,5.51994,55.1994,0.41368255
,,,,,,332.00003,10348.57556,10.34857556,5.53362,55.3362,0.413943022
,,,,,,332.80003,10350.21618,10.35021618,5.54669,55.4669,0.414008647
,,,,,,333.6,10352.96321,10.35296321,5.56019,55.6019,0.414118528
,,,,,,334.40003,10357.22494,10.35722494,5.57337,55.7337,0.414288998
,,,,,,335.2,10359.16135,10.35916135,5.58662,55.8662,0.414366454
,,,,,,336.00003,10366.23567,10.36623567,5.60025,56.0025,0.414649427
,,,,,,336.80003,10363.3821,10.3633821,5.61294,56.1294,0.414535284
,,,,,,337.6,10365.62026,10.36562026,5.62637,56.2637,0.41462481
,,,,,,338.40003,10372.80411,10.37280411,5.64012,56.4012,0.414912164
,,,,,,339.2,10375.96315,10.37596315,5.65331,56.5331,0.415038526
,,,,,,340.00003,10376.93173,10.37693173,5.66662,56.6662,0.415077269
,,,,,,340.80003,10381.13385,10.38113385,5.67994,56.7994,0.415245354
,,,,,,341.6,10384.63861,10.38463861,5.6935,56.935,0.415385544
,,,,,,342.40003,10391.97221,10.39197221,5.70712,57.0712,0.415678888
,,,,,,343.2,10389.74822,10.38974822,5.71981,57.1981,0.415589929
,,,,,,344.00003,10390.95148,10.39095148,5.73319,57.3319,0.415638059
,,,,,,344.80003,10394.6127,10.3946127,5.74669,57.4669,0.415784508
,,,,,,345.6,10400.02257,10.40002257,5.76006,57.6006,0.416000903
,,,,,,346.40003,10399.50252,10.39950252,5.77312,57.7312,0.415980101
,,,,,,347.2,10405.02712,10.40502712,5.78675,57.8675,0.416201085
,,,,,,348.00003,10405.26256,10.40526256,5.79981,57.9981,0.416210502
,,,,,,348.80003,10407.81289,10.40781289,5.81356,58.1356,0.416312516
,,,,,,349.6,10412.39351,10.41239351,5.82669,58.2669,0.41649574
,,,,,,350.40003,10410.13449,10.41013449,5.83962,58.3962,0.41640538
,,,,,,351.2,10412.0858,10.4120858,5.85319,58.5319,0.416483432
,,,,,,352.00003,10419.59226,10.41959226,5.86681,58.6681,0.41678369
,,,,,,352.80003,10418.64976,10.41864976,5.87994,58.7994,0.41674599
,,,,,,353.6,10422.89212,10.42289212,5.89362,58.9362,0.416915685
,,,,,,354.40003,10423.87709,10.42387709,5.90662,59.0662,0.416955084
,,,,,,355.2,10426.71055,10.42671055,5.9205,59.205,0.417068422
,,,,,,356.00003,10430.20338,10.43020338,5.93356,59.3356,0.417208135
,,,,,,356.80003,10426.37005,10.42637005,5.94644,59.4644,0.417054802
,,,,,,357.6,10427.61207,10.42761207,5.95981,59.5981,0.417104483
,,,,,,358.40003,10432.63748,10.43263748,5.97344,59.7344,0.417305499
,,,,,,359.2,10431.97662,10.43197662,5.9865,59.865,0.417279065
,,,,,,360.00003,10433.08973,10.43308973,6,60,0.417323589
,,,,,,360.80003,10436.57735,10.43657735,6.01331,60.1331,0.417463094
,,,,,,361.6,10435.70414,10.43570414,6.02656,60.2656,0.417428166
,,,,,,362.40003,10440.3466,10.4403466,6.0405,60.405,0.417613864
,,,,,,363.2,10436.93945,10.43693945,6.05325,60.5325,0.417477578
,,,,,,364.00003,10432.15618,10.43215618,6.06637,60.6637,0.417286247
,,,,,,364.80003,10432.74105,10.43274105,6.08006,60.8006,0.417309642
,,,,,,365.6,10437.26653,10.43726653,6.09344,60.9344,0.417490661
,,,,,,366.40003,10431.41335,10.43141335,6.10669,61.0669,0.417256534
,,,,,,367.2,10432.16065,10.43216065,6.12019,61.2019,0.417286426
,,,,,,368.00003,10430.1855,10.4301855,6.13344,61.3344,0.41720742
,,,,,,368.80003,10431.74863,10.43174863,6.14712,61.4712,0.417269945
,,,,,,369.6,10427.31702,10.42731702,6.16,61.6,0.417092681
,,,,,,370.40003,10421.39456,10.42139456,6.17306,61.7306,0.416855782
,,,,,,371.2,10420.10561,10.42010561,6.1865,61.865,0.416804224
,,,,,,372.00003,10421.67023,10.42167023,6.20012,62.0012,0.416866809
,,,,,,372.80003,10419.9551,10.4199551,6.21331,62.1331,0.416798204
,,,,,,373.6,10417.27737,10.41727737,6.22681,62.2681,0.416691095
,,,,,,374.40003,10415.80737,10.41580737,6.24,62.4,0.416632295
,,,,,,375.2,10411.4607,10.4114607,6.25344,62.5344,0.416458428
,,,,,,376.00003,10411.99192,10.41199192,6.267,62.67,0.416479677
,,,,,,376.80003,10403.85589,10.40385589,6.27987,62.7987,0.416154236
,,,,,,377.6,10397.50725,10.39750725,6.29306,62.9306,0.41590029
,,,,,,378.40003,10397.04233,10.39704233,6.307,63.07,0.415881693
,,,,,,379.2,10392.26204,10.39226204,6.32006,63.2006,0.415690482
,,,,,,380.00003,10382.64111,10.38264111,6.33337,63.3337,0.415305644
,,,,,,380.80003,10378.54999,10.37854999,6.34675,63.4675,0.415142
,,,,,,381.6,10372.78846,10.37278846,6.36019,63.6019,0.414911538
,,,,,,382.40003,10367.45906,10.36745906,6.37369,63.7369,0.414698362
,,,,,,383.2,10355.32728,10.35532728,6.3865,63.865,0.414213091
,,,,,,384.00003,10345.55286,10.34555286,6.39956,63.9956,0.413822114
,,,,,,384.80003,10339.61251,10.33961251,6.41344,64.1344,0.4135845
,,,,,,385.6,10332.70881,10.33270881,6.42681,64.2681,0.413308352
,,,,,,386.40003,10322.04926,10.32204926,6.44,64.4,0.41288197
,,,,,,387.2,10313.77614,10.31377614,6.45337,64.5337,0.412551046
,,,,,,388.00003,10301.28077,10.30128077,6.46669,64.6669,0.412051231
,,,,,,388.80003,10292.69025,10.29269025,6.48037,64.8037,0.41170761
,,,,,,389.6,10282.52468,10.28252468,6.49344,64.9344,0.411300987
,,,,,,390.40003,10265.18196,10.26518196,6.50644,65.0644,0.410607278
,,,,,,391.2,10253.23197,10.25323197,6.51994,65.1994,0.410129279
,,,,,,392.00003,10243.57229,10.24357229,6.53356,65.3356,0.409742892
,,,,,,392.80003,10228.29488,10.22829488,6.54669,65.4669,0.409131795
,,,,,,393.6,10213.58371,10.21358371,6.56019,65.6019,0.408543348
,,,,,,394.40003,10201.93249,10.20193249,6.57337,65.7337,0.4080773
,,,,,,395.2,10185.51439,10.18551439,6.58669,65.8669,0.407420576
,,,,,,396.00003,10172.10111,10.17210111,6.60025,66.0025,0.406884044
,,,,,,396.80003,10150.89229,10.15089229,6.61294,66.1294,0.406035692
,,,,,,397.6,10134.36094,10.13436094,6.62637,66.2637,0.405374438
,,,,,,398.40003,10121.01769,10.12101769,6.64019,66.4019,0.404840708
,,,,,,399.2,10102.78389,10.10278389,6.65331,66.5331,0.404111356
,,,,,,400.00003,10085.98283,10.08598283,6.66669,66.6669,0.403439313
,,,,,,400.80003,10069.19593,10.06919593,6.67994,66.7994,0.402767837
,,,,,,401.6,10047.94389,10.04794389,6.69356,66.9356,0.401917756
,,,,,,402.40003,10033.35938,10.03335938,6.70706,67.0706,0.401334375
,,,,,,403.2,10009.55924,10.00955924,6.71981,67.1981,0.40038237
,,,,,,404.00003,9987.2157,9.9872157,6.73319,67.3319,0.399488628
,,,,,,404.80003,9967.22579,9.96722579,6.74662,67.4662,0.398689032
,,,,,,405.6,9950.06412,9.95006412,6.76012,67.6012,0.398002565
,,,,,,406.40003,9924.7165,9.9247165,6.77312,67.7312,0.39698866
,,,,,,407.2,9904.72138,9.90472138,6.78675,67.8675,0.396188855
,,,,,,408.00003,9881.09261,9.88109261,6.79981,67.9981,0.395243704
,,,,,,408.80003,9859.80555,9.85980555,6.81362,68.1362,0.394392222
,,,,,,409.6,9837.28319,9.83728319,6.82669,68.2669,0.393491328
,,,,,,410.40003,9808.96428,9.80896428,6.83962,68.3962,0.392358571
,,,,,,411.2,9785.05835,9.78505835,6.85325,68.5325,0.391402334
,,,,,,412.00003,9765.56763,9.76556763,6.86681,68.6681,0.390622705
,,,,,,412.80003,9739.38555,9.73938555,6.87994,68.7994,0.389575422
,,,,,,413.6,9713.78163,9.71378163,6.89362,68.9362,0.388551265
,,,,,,414.40003,9685.92539,9.68592539,6.90662,69.0662,0.387437016
,,,,,,415.2,9662.51716,9.66251716,6.92056,69.2056,0.386500686
,,,,,,416.00003,9637.61657,9.63761657,6.93356,69.3356,0.385504663
,,,,,,416.80003,9604.57548,9.60457548,6.94644,69.4644,0.384183019
,,,,,,417.6,9575.21871,9.57521871,6.95981,69.5981,0.383008748
,,,,,,418.40003,9551.09671,9.55109671,6.97337,69.7337,0.382043868
,,,,,,419.2,9521.72503,9.52172503,6.9865,69.865,0.380869001
,,,,,,420.00003,9492.14175,9.49214175,7.00006,70.0006,0.37968567
,,,,,,420.80003,9464.03295,9.46403295,7.01325,70.1325,0.378561318
,,,,,,421.6,9433.09888,9.43309888,7.02656,70.2656,0.377323955
,,,,,,422.40003,9406.03763,9.40603763,7.0405,70.405,0.376241505
,,,,,,423.2,9373.62388,9.37362388,7.05325,70.5325,0.374944955
,,,,,,424.00003,9337.32688,9.33732688,7.06631,70.6631,0.373493075
,,,,,,424.80003,9307.49252,9.30749252,7.08019,70.8019,0.372299701
,,,,,,425.6,9280.25469,9.28025469,7.09344,70.9344,0.371210188
,,,,,,426.40003,9244.44571,9.24444571,7.10669,71.0669,0.369777828
,,,,,,427.2,9213.10782,9.21310782,7.12019,71.2019,0.368524313
,,,,,,428.00003,9178.21601,9.17821601,7.13344,71.3344,0.36712864
,,,,,,428.80003,9147.93313,9.14793313,7.14706,71.4706,0.365917325
,,,,,,429.6,9110.48129,9.11048129,7.16,71.6,0.364419252
,,,,,,430.40003,9070.65645,9.07065645,7.17306,71.7306,0.362826258
,,,,,,431.2,9037.3233,9.0373233,7.1865,71.865,0.361492932
,,,,,,432.00003,9002.86436,9.00286436,7.20012,72.0012,0.360114574
,,,,,,432.80003,8963.608,8.963608,7.21325,72.1325,0.35854432
,,,,,,433.6,8926.64343,8.92664343,7.22681,72.2681,0.357065737
,,,,,,434.40003,8889.76529,8.88976529,7.24,72.4,0.355590612
,,,,,,435.2,8849.53961,8.84953961,7.25344,72.5344,0.353981584
,,,,,,436.00003,8812.40591,8.81240591,7.267,72.67,0.352496236
,,,,,,436.80003,8766.64966,8.76664966,7.27981,72.7981,0.350665986
,,,,,,437.6,8723.96454,8.72396454,7.29306,72.9306,0.348958582
,,,,,,438.40003,8684.5547,8.6845547,7.30706,73.0706,0.347382188
,,,,,,439.2,8641.28023,8.64128023,7.32,73.2,0.345651209
,,,,,,440.00003,8596.18038,8.59618038,7.33337,73.3337,0.343847215
,,,,,,440.80003,8553.19202,8.55319202,7.34675,73.4675,0.342127681
,,,,,,441.6,8505.27287,8.50527287,7.36025,73.6025,0.340210915
,,,,,,442.40003,8460.80035,8.46080035,7.37369,73.7369,0.338432014
,,,,,,443.2,8406.64357,8.40664357,7.3865,73.865,0.336265743
,,,,,,444.00003,8350.50568,8.35050568,7.39956,73.9956,0.334020227
,,,,,,444.80003,8278.20376,8.27820376,7.41344,74.1344,0.33112815
,,,,,,445.6,-68.03643,-0.06803643,7.42669,74.2669,-0.002721457
,,,,,,446.40003,-67.1715,-0.0671715,7.43994,74.3994,-0.00268686
,,,,,,447.2,-67.02853,-0.06702853,7.45344,74.5344,-0.002681141
,,,,,,448.00003,-66.47878,-0.06647878,7.46669,74.6669,-0.002659151
,,,,,,448.80003,-66.24475,-0.06624475,7.4805,74.805,-0.00264979
,,,,,,449.6,-66.02411,-0.06602411,7.49337,74.9337,-0.002640964
,,,,,,450.40003,-65.87653,-0.06587653,7.50637,75.0637,-0.002635061
,,,,,,451.2,-65.50286,-0.06550286,7.51987,75.1987,-0.002620114
,,,,,,452.00003,-64.47365,-0.06447365,7.53362,75.3362,-0.002578946
,,,,,,452.80003,-64.20905,-0.06420905,7.54656,75.4656,-0.002568362
,,,,,,453.60003,-63.69606,-0.06369606,7.56006,75.6006,-0.002547842
,,,,,,454.40003,-63.57525,-0.06357525,7.57331,75.7331,-0.00254301
,,,,,,455.2,-63.43311,-0.06343311,7.58687,75.8687,-0.002537324
,,,,,,456.00003,-63.25803,-0.06325803,7.60019,76.0019,-0.002530321
,,,,,,456.80003,-63.5372,-0.0635372,7.613,76.13,-0.002541488
,,,,,,457.60003,-63.57833,-0.06357833,7.62644,76.2644,-0.002543133
,,,,,,458.40003,-63.6914,-0.0636914,7.64025,76.4025,-0.002547656
,,,,,,459.2,-63.71599,-0.06371599,7.65325,76.5325,-0.00254864
,,,,,,460.00003,-64.78219,-0.06478219,7.66669,76.6669,-0.002591288
,,,,,,460.80003,-63.71919,-0.06371919,7.68,76.8,-0.002548768
,,,,,,461.60003,-63.11474,-0.06311474,7.6935,76.935,-0.00252459
,,,,,,462.40003,-62.79064,-0.06279064,7.70712,77.0712,-0.002511626
,,,,,,463.2,-62.87054,-0.06287054,7.71981,77.1981,-0.002514822
,,,,,,464.00003,-62.23582,-0.06223582,7.73306,77.3306,-0.002489433
,,,,,,464.80003,-62.691,-0.062691,7.74669,77.4669,-0.00250764
,,,,,,465.60003,-62.5366,-0.0625366,7.76006,77.6006,-0.002501464
,,,,,,466.40003,-62.59526,-0.06259526,7.77312,77.7312,-0.00250381
,,,,,,467.2,-62.28471,-0.06228471,7.78681,77.8681,-0.002491388
,,,,,,468.00003,-62.16851,-0.06216851,7.79987,77.9987,-0.00248674
,,,,,,468.80003,-62.17196,-0.06217196,7.81381,78.1381,-0.002486878
,,,,,,469.60003,-62.41321,-0.06241321,7.82669,78.2669,-0.002496528
,,,,,,470.40003,-62.13312,-0.06213312,7.83962,78.3962,-0.002485325
,,,,,,471.2,-62.15568,-0.06215568,7.85325,78.5325,-0.002486227
,,,,,,472.00003,-62.21183,-0.06221183,7.86681,78.6681,-0.002488473
,,,,,,472.80003,-61.99396,-0.06199396,7.87994,78.7994,-0.002479758
,,,,,,473.60003,-61.55033,-0.06155033,7.8935,78.935,-0.002462013
,,,,,,474.40003,-61.34288,-0.06134288,7.90662,79.0662,-0.002453715
,,,,,,475.2,-61.20481,-0.06120481,7.92044,79.2044,-0.002448192
,,,,,,476.00003,-61.13803,-0.06113803,7.93356,79.3356,-0.002445521
,,,,,,476.80003,-60.70037,-0.06070037,7.94637,79.4637,-0.002428015
,,,,,,477.60003,-60.11592,-0.06011592,7.95981,79.5981,-0.002404637
,,,,,,478.40003,-60.44965,-0.06044965,7.97356,79.7356,-0.002417986
,,,,,,479.2,-60.12791,-0.06012791,7.98656,79.8656,-0.002405116
,,,,,,480.00003,-60.60997,-0.06060997,7.99994,79.9994,-0.002424399
,,,,,,480.80003,-60.23556,-0.06023556,8.01344,80.1344,-0.002409422
,,,,,,481.60003,-59.50315,-0.05950315,8.02669,80.2669,-0.002380126
,,,,,,482.40003,-59.48505,-0.05948505,8.04056,80.4056,-0.002379402
,,,,,,483.2,-59.53041,-0.05953041,8.05319,80.5319,-0.002381216
,,,,,,484.00003,-59.5942,-0.0595942,8.06631,80.6631,-0.002383768
,,,,,,484.80003,-59.66438,-0.05966438,8.08012,80.8012,-0.002386575
,,,,,,485.60003,-59.29002,-0.05929002,8.09344,80.9344,-0.002371601
,,,,,,486.40003,-59.29474,-0.05929474,8.10656,81.0656,-0.00237179
,,,,,,487.2,-59.36654,-0.05936654,8.12019,81.2019,-0.002374662
,,,,,,488.00003,-59.32284,-0.05932284,8.13331,81.3331,-0.002372914
,,,,,,488.80003,-58.97789,-0.05897789,8.14725,81.4725,-0.002359116
,,,,,,489.60003,-59.3255,-0.0593255,8.16,81.6,-0.00237302
,,,,,,490.40003,-58.92364,-0.05892364,8.173,81.73,-0.002356946
,,,,,,491.2,-59.03449,-0.05903449,8.1865,81.865,-0.00236138
,,,,,,492.00003,-59.42784,-0.05942784,8.20019,82.0019,-0.002377114
,,,,,,492.80003,-58.66308,-0.05866308,8.21319,82.1319,-0.002346523
,,,,,,493.60003,-59.24357,-0.05924357,8.22675,82.2675,-0.002369743
,,,,,,494.40003,-58.84799,-0.05884799,8.24,82.4,-0.00235392
,,,,,,495.2,-59.34021,-0.05934021,8.25362,82.5362,-0.002373608
,,,,,,496.00003,-59.09557,-0.05909557,8.26694,82.6694,-0.002363823
,,,,,,496.80003,-58.96532,-0.05896532,8.27975,82.7975,-0.002358613
,,,,,,497.60003,-58.68414,-0.05868414,8.29306,82.9306,-0.002347366
,,,,,,498.40003,-59.23114,-0.05923114,8.307,83.07,-0.002369246
,,,,,,499.2,-58.89544,-0.05889544,8.32,83.2,-0.002355818
,,,,,,500.00003,-58.62386,-0.05862386,8.33331,83.3331,-0.002344954
,,,,,,500.80003,-58.91289,-0.05891289,8.34669,83.4669,-0.002356516
,,,,,,501.60003,-58.68122,-0.05868122,8.36012,83.6012,-0.002347249
,,,,,,502.40003,-59.00981,-0.05900981,8.37375,83.7375,-0.002360392
,,,,,,503.2,-58.6486,-0.0586486,8.38644,83.8644,-0.002345944
,,,,,,504.00003,-58.75823,-0.05875823,8.39962,83.9962,-0.002350329
,,,,,,504.80003,-58.79017,-0.05879017,8.41337,84.1337,-0.002351607
,,,,,,505.60003,-58.66384,-0.05866384,8.42675,84.2675,-0.002346554
,,,,,,506.40003,-58.85138,-0.05885138,8.43994,84.3994,-0.002354055
,,,,,,507.2,-58.27573,-0.05827573,8.45344,84.5344,-0.002331029
,,,,,,508.00003,-58.68729,-0.05868729,8.46669,84.6669,-0.002347492
,,,,,,508.80003,-58.70253,-0.05870253,8.48044,84.8044,-0.002348101
,,,,,,509.60003,-58.57648,-0.05857648,8.49331,84.9331,-0.002343059
,,,,,,510.40003,-58.51082,-0.05851082,8.50637,85.0637,-0.002340433
,,,,,,511.2,-58.60624,-0.05860624,8.51987,85.1987,-0.00234425
,,,,,,512,-58.48658,-0.05848658,8.53356,85.3356,-0.002339463
,,,,,,512.80006,-58.29453,-0.05829453,8.54656,85.4656,-0.002331781
,,,,,,513.60003,-58.14703,-0.05814703,8.56012,85.6012,-0.002325881
,,,,,,514.40003,-58.01718,-0.05801718,8.57331,85.7331,-0.002320687
,,,,,,515.2,-58.33691,-0.05833691,8.58681,85.8681,-0.002333476
,,,,,,516,-58.24983,-0.05824983,8.60019,86.0019,-0.002329993
,,,,,,516.80006,-58.33666,-0.05833666,8.613,86.13,-0.002333466
,,,,,,517.60003,-58.24937,-0.05824937,8.62637,86.2637,-0.002329975
,,,,,,518.40003,-58.65282,-0.05865282,8.64025,86.4025,-0.002346113
,,,,,,519.2,-58.27927,-0.05827927,8.65331,86.5331,-0.002331171
,,,,,,520,-58.6881,-0.0586881,8.66656,86.6656,-0.002347524
,,,,,,520.80006,-58.55401,-0.05855401,8.68006,86.8006,-0.00234216
,,,,,,521.60003,-58.00939,-0.05800939,8.69344,86.9344,-0.002320376
,,,,,,522.40003,-58.28378,-0.05828378,8.70712,87.0712,-0.002331351
,,,,,,523.2,-58.20234,-0.05820234,8.71981,87.1981,-0.002328094
,,,,,,524,-58.27737,-0.05827737,8.73306,87.3306,-0.002331095
,,,,,,524.80006,-58.30407,-0.05830407,8.74662,87.4662,-0.002332163
,,,,,,525.60006,-58.18604,-0.05818604,8.76006,87.6006,-0.002327442
,,,,,,526.4,-58.15197,-0.05815197,8.77312,87.7312,-0.002326079
,,,,,,527.2,-58.21309,-0.05821309,8.78681,87.8681,-0.002328524
,,,,,,528,-58.08657,-0.05808657,8.79987,87.9987,-0.002323463
,,,,,,528.80006,-58.11644,-0.05811644,8.81387,88.1387,-0.002324658
,,,,,,529.60006,-58.40854,-0.05840854,8.82662,88.2662,-0.002336342
,,,,,,530.4,-58.14011,-0.05814011,8.83962,88.3962,-0.002325604
,,,,,,531.2,-58.13398,-0.05813398,8.85325,88.5325,-0.002325359
,,,,,,532,-58.37868,-0.05837868,8.86687,88.6687,-0.002335147
,,,,,,532.80006,-58.02058,-0.05802058,8.87987,88.7987,-0.002320823
,,,,,,533.60006,-58.13583,-0.05813583,8.8935,88.935,-0.002325433
,,,,,,534.4,-57.90151,-0.05790151,8.90662,89.0662,-0.00231606
,,,,,,534.89,-57.85235,-0.05785235,8.91487,89.1487,-0.002314094